Workbook
Name ServicesList: Lists!$A$2:$A$11
Name UtilitiesList: Lists!$B$2:$B$42

Sheet Calculator
A1: Inputs
A2: Home Type | B2: Count | C2: Demand per Home | D2: Demand Contribution | F2: Total Homes | H2: =SUM(B3:B9)
A3: Regular RZ | B3: 0 | C3: 35 | D3: =B3*C3
A4: 4-tier Homes (Kyoto/Florentine/Art Nouveau/Latin American) | B4: 0 | C4: 30 | D4: =B4*C4
A5: Airport-Related (Paris/London/Tokyo) | B5: 0 | C5: 40 | D5: =B5*C5
A6: Old Town House | B6: 0 | C6: 2 | D6: =B6*C6
A7: Epic Buildings | B7: 0 | C7: 45 | D7: =B7*C7
A8: Regional Buildings | B8: 0 | C8: 45 | D8: =B8*C8
A9: Omega Buildings | B9: 0 | C9: 50 | D9: =B9*C9
A11: TOTAL DEMAND (per service) | D11: =SUM(D3:D9)
A14: Utilities (Capacities) → Buildings Needed → TOTAL cost
A15: Service | B15: Utility | C15: Max Level | D15: Services needed | E15: Chosen Level | F15: Key | G15: Capacity @ Level | H15: Spare Capacity | I15: Total cost @ Level
A16: Power | B16: Wind Power Plant | C16: 3 | D16: =IF($G16="","",CEILING(D11/$G16,1)) | E16: 3 | F16: =$B16&"|"&MIN($E16,$C16) | G16: =IFERROR(VLOOKUP($F16,Data!$A:$F,5,FALSE),"") | H16: =IF($D16="","",($D16*$G16)-D11) | I16: =IF($D16="","",$D16*IFERROR(VLOOKUP($F16,Data!$A:$F,6,FALSE),0))
A17: Power | B17: Coal Power Plant | C17: 3 | D17: =IF($G17="","",CEILING(D11/$G17,1)) | E17: 3 | F17: =$B17&"|"&MIN($E17,$C17) | G17: =IFERROR(VLOOKUP($F17,Data!$A:$F,5,FALSE),"") | H17: =IF($D17="","",($D17*$G17)-D11) | I17: =IF($D17="","",$D17*IFERROR(VLOOKUP($F17,Data!$A:$F,6,FALSE),0))
A18: Power | B18: Deluxe Wind Power Plant | C18: 5 | D18: =IF($G18="","",CEILING(D11/$G18,1)) | E18: 5 | F18: =$B18&"|"&MIN($E18,$C18) | G18: =IFERROR(VLOOKUP($F18,Data!$A:$F,5,FALSE),"") | H18: =IF($D18="","",($D18*$G18)-D11) | I18: =IF($D18="","",$D18*IFERROR(VLOOKUP($F18,Data!$A:$F,6,FALSE),0))
A19: Power | B19: Solar Power Plant | C19: 5 | D19: =IF($G19="","",CEILING(D11/$G19,1)) | E19: 5 | F19: =$B19&"|"&MIN($E19,$C19) | G19: =IFERROR(VLOOKUP($F19,Data!$A:$F,5,FALSE),"") | H19: =IF($D19="","",($D19*$G19)-D11) | I19: =IF($D19="","",$D19*IFERROR(VLOOKUP($F19,Data!$A:$F,6,FALSE),0))
A20: Power | B20: Oil Power Plant | C20: 5 | D20: =IF($G20="","",CEILING(D11/$G20,1)) | E20: 5 | F20: =$B20&"|"&MIN($E20,$C20) | G20: =IFERROR(VLOOKUP($F20,Data!$A:$F,5,FALSE),"") | H20: =IF($D20="","",($D20*$G20)-D11) | I20: =IF($D20="","",$D20*IFERROR(VLOOKUP($F20,Data!$A:$F,6,FALSE),0))
A21: Power | B21: Nuclear Power Plant | C21: 8 | D21: =IF($G21="","",CEILING(D11/$G21,1)) | E21: 8 | F21: =$B21&"|"&MIN($E21,$C21) | G21: =IFERROR(VLOOKUP($F21,Data!$A:$F,5,FALSE),"") | H21: =IF($D21="","",($D21*$G21)-D11) | I21: =IF($D21="","",$D21*IFERROR(VLOOKUP($F21,Data!$A:$F,6,FALSE),0))
A22: Power | B22: Fusion Power Plant | C22: 10 | D22: =IF($G22="","",CEILING(D11/$G22,1)) | E22: 10 | F22: =$B22&"|"&MIN($E22,$C22) | G22: =IFERROR(VLOOKUP($F22,Data!$A:$F,5,FALSE),"") | H22: =IF($D22="","",($D22*$G22)-D11) | I22: =IF($D22="","",$D22*IFERROR(VLOOKUP($F22,Data!$A:$F,6,FALSE),0))
A23: Power | B23: Omega Power Plant | C23: 10 | D23: =IF($G23="","",CEILING(D11/$G23,1)) | E23: 10 | F23: =$B23&"|"&MIN($E23,$C23) | G23: =IFERROR(VLOOKUP($F23,Data!$A:$F,5,FALSE),"") | H23: =IF($D23="","",($D23*$G23)-D11) | I23: =IF($D23="","",$D23*IFERROR(VLOOKUP($F23,Data!$A:$F,6,FALSE),0))
A24: Water | B24: Basic Water Tower | C24: 3 | D24: =IF($G24="","",CEILING(D11/$G24,1)) | E24: 3 | F24: =$B24&"|"&MIN($E24,$C24) | G24: =IFERROR(VLOOKUP($F24,Data!$A:$F,5,FALSE),"") | H24: =IF($D24="","",($D24*$G24)-D11) | I24: =IF($D24="","",$D24*IFERROR(VLOOKUP($F24,Data!$A:$F,6,FALSE),0))
A25: Water | B25: Water Pumping Station | C25: 5 | D25: =IF($G25="","",CEILING(D11/$G25,1)) | E25: 5 | F25: =$B25&"|"&MIN($E25,$C25) | G25: =IFERROR(VLOOKUP($F25,Data!$A:$F,5,FALSE),"") | H25: =IF($D25="","",($D25*$G25)-D11) | I25: =IF($D25="","",$D25*IFERROR(VLOOKUP($F25,Data!$A:$F,6,FALSE),0))
A26: Water | B26: Saltwater Treatment Plant | C26: 8 | D26: =IF($G26="","",CEILING(D11/$G26,1)) | E26: 8 | F26: =$B26&"|"&MIN($E26,$C26) | G26: =IFERROR(VLOOKUP($F26,Data!$A:$F,5,FALSE),"") | H26: =IF($D26="","",($D26*$G26)-D11) | I26: =IF($D26="","",$D26*IFERROR(VLOOKUP($F26,Data!$A:$F,6,FALSE),0))
A27: Water | B27: Fresh Water Pumping Station | C27: 10 | D27: =IF($G27="","",CEILING(D11/$G27,1)) | E27: 10 | F27: =$B27&"|"&MIN($E27,$C27) | G27: =IFERROR(VLOOKUP($F27,Data!$A:$F,5,FALSE),"") | H27: =IF($D27="","",($D27*$G27)-D11) | I27: =IF($D27="","",$D27*IFERROR(VLOOKUP($F27,Data!$A:$F,6,FALSE),0))
A28: Water | B28: Omega Water Tower | C28: 10 | D28: =IF($G28="","",CEILING(D11/$G28,1)) | E28: 10 | F28: =$B28&"|"&MIN($E28,$C28) | G28: =IFERROR(VLOOKUP($F28,Data!$A:$F,5,FALSE),"") | H28: =IF($D28="","",($D28*$G28)-D11) | I28: =IF($D28="","",$D28*IFERROR(VLOOKUP($F28,Data!$A:$F,6,FALSE),0))
A29: Sewage | B29: Small Sewage Outflow Pipe | C29: 5 | D29: =IF($G29="","",CEILING(D11/$G29,1)) | E29: 5 | F29: =$B29&"|"&MIN($E29,$C29) | G29: =IFERROR(VLOOKUP($F29,Data!$A:$F,5,FALSE),"") | H29: =IF($D29="","",($D29*$G29)-D11) | I29: =IF($D29="","",$D29*IFERROR(VLOOKUP($F29,Data!$A:$F,6,FALSE),0))
A30: Sewage | B30: Basic Sewage Outflow Pipe | C30: 8 | D30: =IF($G30="","",CEILING(D11/$G30,1)) | E30: 8 | F30: =$B30&"|"&MIN($E30,$C30) | G30: =IFERROR(VLOOKUP($F30,Data!$A:$F,5,FALSE),"") | H30: =IF($D30="","",($D30*$G30)-D11) | I30: =IF($D30="","",$D30*IFERROR(VLOOKUP($F30,Data!$A:$F,6,FALSE),0))
A31: Sewage | B31: Deluxe Sewage Treatment Plant | C31: 10 | D31: =IF($G31="","",CEILING(D11/$G31,1)) | E31: 10 | F31: =$B31&"|"&MIN($E31,$C31) | G31: =IFERROR(VLOOKUP($F31,Data!$A:$F,5,FALSE),"") | H31: =IF($D31="","",($D31*$G31)-D11) | I31: =IF($D31="","",$D31*IFERROR(VLOOKUP($F31,Data!$A:$F,6,FALSE),0))
A32: Sewage | B32: Omega Sewage Treatment Plant | C32: 10 | D32: =IF($G32="","",CEILING(D11/$G32,1)) | E32: 10 | F32: =$B32&"|"&MIN($E32,$C32) | G32: =IFERROR(VLOOKUP($F32,Data!$A:$F,5,FALSE),"") | H32: =IF($D32="","",($D32*$G32)-D11) | I32: =IF($D32="","",$D32*IFERROR(VLOOKUP($F32,Data!$A:$F,6,FALSE),0))
A33: Waste | B33: Small Garbage Dump | C33: 5 | D33: =IF($G33="","",CEILING(D11/$G33,1)) | E33: 5 | F33: =$B33&"|"&MIN($E33,$C33) | G33: =IFERROR(VLOOKUP($F33,Data!$A:$F,5,FALSE),"") | H33: =IF($D33="","",($D33*$G33)-D11) | I33: =IF($D33="","",$D33*IFERROR(VLOOKUP($F33,Data!$A:$F,6,FALSE),0))
A34: Waste | B34: Garbage Dump | C34: 5 | D34: =IF($G34="","",CEILING(D11/$G34,1)) | E34: 5 | F34: =$B34&"|"&MIN($E34,$C34) | G34: =IFERROR(VLOOKUP($F34,Data!$A:$F,5,FALSE),"") | H34: =IF($D34="","",($D34*$G34)-D11) | I34: =IF($D34="","",$D34*IFERROR(VLOOKUP($F34,Data!$A:$F,6,FALSE),0))
A35: Waste | B35: Garbage Incinerator | C35: 8 | D35: =IF($G35="","",CEILING(D11/$G35,1)) | E35: 8 | F35: =$B35&"|"&MIN($E35,$C35) | G35: =IFERROR(VLOOKUP($F35,Data!$A:$F,5,FALSE),"") | H35: =IF($D35="","",($D35*$G35)-D11) | I35: =IF($D35="","",$D35*IFERROR(VLOOKUP($F35,Data!$A:$F,6,FALSE),0))
A36: Waste | B36: Recycling Center | C36: 10 | D36: =IF($G36="","",CEILING(D11/$G36,1)) | E36: 10 | F36: =$B36&"|"&MIN($E36,$C36) | G36: =IFERROR(VLOOKUP($F36,Data!$A:$F,5,FALSE),"") | H36: =IF($D36="","",($D36*$G36)-D11) | I36: =IF($D36="","",$D36*IFERROR(VLOOKUP($F36,Data!$A:$F,6,FALSE),0))
A37: Waste | B37: Omega Recycling Center | C37: 10 | D37: =IF($G37="","",CEILING(D11/$G37,1)) | E37: 10 | F37: =$B37&"|"&MIN($E37,$C37) | G37: =IFERROR(VLOOKUP($F37,Data!$A:$F,5,FALSE),"") | H37: =IF($D37="","",($D37*$G37)-D11) | I37: =IF($D37="","",$D37*IFERROR(VLOOKUP($F37,Data!$A:$F,6,FALSE),0))
A38: Fire | B38: Small Fire Station | C38: 3 | D38: =IF($G38="","",CEILING(D11/$G38,1)) | E38: 3 | F38: =$B38&"|"&MIN($E38,$C38) | G38: =IFERROR(VLOOKUP($F38,Data!$A:$F,5,FALSE),"") | H38: =IF($D38="","",($D38*$G38)-D11) | I38: =IF($D38="","",$D38*IFERROR(VLOOKUP($F38,Data!$A:$F,6,FALSE),0))
A39: Fire | B39: Basic Fire Station | C39: 5 | D39: =IF($G39="","",CEILING(D11/$G39,1)) | E39: 5 | F39: =$B39&"|"&MIN($E39,$C39) | G39: =IFERROR(VLOOKUP($F39,Data!$A:$F,5,FALSE),"") | H39: =IF($D39="","",($D39*$G39)-D11) | I39: =IF($D39="","",$D39*IFERROR(VLOOKUP($F39,Data!$A:$F,6,FALSE),0))
A40: Fire | B40: Deluxe Fire Station | C40: 8 | D40: =IF($G40="","",CEILING(D11/$G40,1)) | E40: 8 | F40: =$B40&"|"&MIN($E40,$C40) | G40: =IFERROR(VLOOKUP($F40,Data!$A:$F,5,FALSE),"") | H40: =IF($D40="","",($D40*$G40)-D11) | I40: =IF($D40="","",$D40*IFERROR(VLOOKUP($F40,Data!$A:$F,6,FALSE),0))
A41: Police | B41: Small Police Station | C41: 3 | D41: =IF($G41="","",CEILING(D11/$G41,1)) | E41: 3 | F41: =$B41&"|"&MIN($E41,$C41) | G41: =IFERROR(VLOOKUP($F41,Data!$A:$F,5,FALSE),"") | H41: =IF($D41="","",($D41*$G41)-D11) | I41: =IF($D41="","",$D41*IFERROR(VLOOKUP($F41,Data!$A:$F,6,FALSE),0))
A42: Police | B42: Basic Police Station | C42: 5 | D42: =IF($G42="","",CEILING(D11/$G42,1)) | E42: 5 | F42: =$B42&"|"&MIN($E42,$C42) | G42: =IFERROR(VLOOKUP($F42,Data!$A:$F,5,FALSE),"") | H42: =IF($D42="","",($D42*$G42)-D11) | I42: =IF($D42="","",$D42*IFERROR(VLOOKUP($F42,Data!$A:$F,6,FALSE),0))
A43: Police | B43: Police Precinct | C43: 8 | D43: =IF($G43="","",CEILING(D11/$G43,1)) | E43: 8 | F43: =$B43&"|"&MIN($E43,$C43) | G43: =IFERROR(VLOOKUP($F43,Data!$A:$F,5,FALSE),"") | H43: =IF($D43="","",($D43*$G43)-D11) | I43: =IF($D43="","",$D43*IFERROR(VLOOKUP($F43,Data!$A:$F,6,FALSE),0))
...

Sheet Data
A1: Key | B1: Service | C1: Building | D1: Level | E1: Capacity | F1: CumCost | G1: MaxLevel
A2: Wind Power Plant|1 | B2: Power | C2: Wind Power Plant | D2: 1 | E2: 6 | F2: 1500 | G2: 3
A3: Wind Power Plant|2 | B3: Power | C3: Wind Power Plant | D3: 2 | E3: 12 | F3: 3250 | G3: 3
A4: Wind Power Plant|3 | B4: Power | C4: Wind Power Plant | D4: 3 | E4: 20 | F4: 5250 | G4: 3
A5: Coal Power Plant|1 | B5: Power | C5: Coal Power Plant | D5: 1 | E5: 10 | F5: 1000 | G5: 3
A6: Coal Power Plant|2 | B6: Power | C6: Coal Power Plant | D6: 2 | E6: 25 | F6: 2250 | G6: 3
A7: Coal Power Plant|3 | B7: Power | C7: Coal Power Plant | D7: 3 | E7: 35 | F7: 3750 | G7: 3
A8: Deluxe Wind Power Plant|1 | B8: Power | C8: Deluxe Wind Power Plant | D8: 1 | E8: 15 | F8: 2000 | G8: 5
A9: Deluxe Wind Power Plant|2 | B9: Power | C9: Deluxe Wind Power Plant | D9: 2 | E9: 30 | F9: 4250 | G9: 5
A10: Deluxe Wind Power Plant|3 | B10: Power | C10: Deluxe Wind Power Plant | D10: 3 | E10: 55 | F10: 6750 | G10: 5
A11: Deluxe Wind Power Plant|4 | B11: Power | C11: Deluxe Wind Power Plant | D11: 4 | E11: 75 | F11: 9500 | G11: 5
A12: Deluxe Wind Power Plant|5 | B12: Power | C12: Deluxe Wind Power Plant | D12: 5 | E12: 90 | F12: 12500 | G12: 5
A13: Solar Power Plant|1 | B13: Power | C13: Solar Power Plant | D13: 1 | E13: 20 | F13: 3000 | G13: 5
... A298: Deluxe Drone Base|10 | B298: Drones | C298: Deluxe Drone Base | D298: 10 | E298: 900 | F298: 147500 | G298: 10

Sheet Lists
A1: Services | B1: Utilities
A2: Power | B2: Wind Power Plant
A3: Water | B3: Coal Power Plant
A4: Sewage | B4: Deluxe Wind Power Plant
A5: Waste | B5: Solar Power Plant
A6: Fire | B6: Oil Power Plant
A7: Police | B7: Nuclear Power Plant
A8: Health | B8: Fusion Power Plant
A9: Regional Services | B9: Omega Power Plant
A10: ControlNet | B10: Basic Water Tower
A11: Drones | B11: Water Pumping Station
B12: Saltwater Treatment Plant
B13: Fresh Water Pumping Station
B14: Omega Water Tower
B15: Small Sewage Outflow Pipe
B16: Basic Sewage Outflow Pipe
B17: Deluxe Sewage Treatment Plant
B18: Omega Sewage Treatment Plant
B19: Small Garbage Dump
B20: Garbage Dump
B21: Garbage Incinerator
B22: Recycling Center
B23: Omega Recycling Center
... B42: Deluxe Drone Base
